Workbook

Sheet Mideer
A1: NINGBO FREE EXPLORATION TOYS MANUFACTURING CO.LTD TEL: 86-574 87253132 Email: mideeroverseas@mideertoys.com
A4: Proforma Invoice
A5: Sold To: | B5: Jacksonway Limited | C5: Date: | D5: 9th June, 2026
A6: ADD: | B6: 82a James Carter Road, Mildenhall, Suffolk, United Kingdom, IP28 7DE | C6: TERMS OF: DELIVERY: | D6: FOB Ningbo | E6: UK_Chosen by Chloe
A7: CONTACT: | B7: Dongchen Shan/闪冬晨 | C7: PI No.: | D7: MDUK20260716001
A8: TEL: | B8: +44 7454020147
A10: Item# | B10: Discription | C10: Unit Price(RMB) | D10: pcs | E10: Amount（RMB） | F10: pcs/ctn | G10: CTNS | H10: remark | I10: weight | J10: total weight | K10: cbm | L10: total cbm
A11: MD1492-CT01 | B11: mideer Artist Fairytale Puzzle - Little Red Riding Hood | C11: 29.4975 | D11: 12 | E11: =C11*D11 -> 353.97 | F11: =VLOOKUP(A11,[2]产品数据!$A:$AG,32,0) -> 27 | G11: =D11/F11 -> 0.44444444 | I11: =VLOOKUP(A11,[2]产品数据!$A:$R,16,0) -> 0.4 | J11: =I11*D11 -> 4.8 | K11: =VLOOKUP(A11,[2]产品数据!$A:$AE,29,0) -> 0.07675668 | L11: =K11*G11 -> 0.03411408
A12: MD1494-CT01 | B12: mideer Artist Fairytale Puzzle - Thumbelina | C12: 29.4975 | D12: 12 | E12: =C12*D12 -> 353.97 | F12: =VLOOKUP(A12,[2]产品数据!$A:$AG,32,0) -> 27 | G12: =D12/F12 -> 0.44444444 | I12: =VLOOKUP(A12,[2]产品数据!$A:$R,16,0) -> 0.45 | J12: =I12*D12 -> 5.4 | K12: =VLOOKUP(A12,[2]产品数据!$A:$AE,29,0) -> 0.07735833 | L12: =K12*G12 -> 0.03438148
A13: MD1039 | B13: =VLOOKUP(A13,'[1]July 2026'!$B:$G,2,0) -> mideer Magnets - Boy&Girl | C13: 37.5015 | D13: 24 | E13: =C13*D13 -> 900.036 | F13: =VLOOKUP(A13,[2]产品数据!$A:$AG,32,0) -> 12 | G13: =D13/F13 -> 2 | I13: =VLOOKUP(A13,[2]产品数据!$A:$R,16,0) -> 0.85 | J13: =I13*D13 -> 20.4 | K13: =VLOOKUP(A13,[2]产品数据!$A:$AE,29,0) -> 0.0342258 | L13: =K13*G13 -> 0.0684516
A14: MD1419 | B14: =VLOOKUP(A14,'[1]July 2026'!$B:$G,2,0) -> mideer Glow Pop Tube | C14: 19.0095 | D14: 12 | E14: =C14*D14 -> 228.114 | F14: =VLOOKUP(A14,[2]产品数据!$A:$AG,32,0) -> 24 | G14: =D14/F14 -> 0.5 | I14: =VLOOKUP(A14,[2]产品数据!$A:$R,16,0) -> 0.35 | J14: =I14*D14 -> 4.2 | K14: =VLOOKUP(A14,[2]产品数据!$A:$AE,29,0) -> 0.05779755 | L14: =K14*G14 -> 0.028898775
A15: MD3400 | B15: =VLOOKUP(A15,'[1]July 2026'!$B:$G,2,0) -> mideer Magnetic Cube Building Blocks | C15: 34.9485 | D15: 30 | E15: =C15*D15 -> 1048.455 | F15: =VLOOKUP(A15,[2]产品数据!$A:$AG,32,0) -> 48 | G15: =D15/F15 -> 0.625 | I15: =VLOOKUP(A15,[2]产品数据!$A:$R,16,0) -> 0.23 | J15: =I15*D15 -> 6.9 | K15: =VLOOKUP(A15,[2]产品数据!$A:$AE,29,0) -> 0.03675672 | L15: =K15*G15 -> 0.02297295
A16: MD6283 | B16: =VLOOKUP(A16,'[1]July 2026'!$B:$G,2,0) -> mideer 250 Colourful Blocks | C16: 117.8175 | D16: 6 | E16: =C16*D16 -> 706.905 | F16: =VLOOKUP(A16,[2]产品数据!$A:$AG,32,0) -> 4 | G16: =D16/F16 -> 1.5 | I16: =VLOOKUP(A16,[2]产品数据!$A:$R,16,0) -> 2.47 | J16: =I16*D16 -> 14.82 | K16: =VLOOKUP(A16,[2]产品数据!$A:$AE,29,0) -> 0.0441674 | L16: =K16*G16 -> 0.0662511
A17: MD1501 | B17: =VLOOKUP(A17,'[1]July 2026'!$B:$G,2,0) -> mideer Mellow Dough -12colours | C17: 54.51 | D17: 6 | E17: =C17*D17 -> 327.06 | F17: =VLOOKUP(A17,[2]产品数据!$A:$AG,32,0) -> 6 | G17: =D17/F17 -> 1 | I17: =VLOOKUP(A17,[2]产品数据!$A:$R,16,0) -> 1.53 | J17: =I17*D17 -> 9.18 | K17: =VLOOKUP(A17,[2]产品数据!$A:$AE,29,0) -> 0.02508732 | L17: =K17*G17 -> 0.02508732
A18: MD1590 | B18: =VLOOKUP(A18,'[1]July 2026'!$B:$G,2,0) -> mideer doodle drawing book | C18: 14.9385 | D18: 12 | E18: =C18*D18 -> 179.262 | F18: =VLOOKUP(A18,[2]产品数据!$A:$AG,32,0) -> 20 | G18: =D18/F18 -> 0.6 | I18: =VLOOKUP(A18,[2]产品数据!$A:$R,16,0) -> 0.6 | J18: =I18*D18 -> 7.2 | K18: =VLOOKUP(A18,[2]产品数据!$A:$AE,29,0) -> 0.01879416 | L18: =K18*G18 -> 0.011276496
A19: MD1614 | B19: =VLOOKUP(A19,'[1]July 2026'!$B:$G,2,0) -> mideer Acrylic Markers-36 | C19: 64.9635 | D19: 6 | E19: =C19*D19 -> 389.781 | F19: =VLOOKUP(A19,[2]产品数据!$A:$AG,32,0) -> 24 | G19: =D19/F19 -> 0.25 | I19: =VLOOKUP(A19,[2]产品数据!$A:$R,16,0) -> 0.57 | J19: =I19*D19 -> 3.42 | K19: =VLOOKUP(A19,[2]产品数据!$A:$AE,29,0) -> 0.045056 | L19: =K19*G19 -> 0.011264
A20: CT0615 | B20: =VLOOKUP(A20,'[1]July 2026'!$B:$G,2,0) -> mideer Imagine & Create Sketchbook – Little World | C20: 10.484895 | D20: 12 | E20: =C20*D20 -> 125.81874 | F20: =VLOOKUP(A20,[2]产品数据!$A:$AG,32,0) -> 40 | G20: =D20/F20 -> 0.3 | I20: =VLOOKUP(A20,[2]产品数据!$A:$R,16,0) -> 0.255 | J20: =I20*D20 -> 3.06 | K20: =VLOOKUP(A20,[2]产品数据!$A:$AE,29,0) -> 0.0168345 | L20: =K20*G20 -> 0.00505035
A21: CT0616 | B21: =VLOOKUP(A21,'[1]July 2026'!$B:$G,2,0) -> mideer Imagine & Create Sketchbook – Big Dreams | C21: 10.484895 | D21: 12 | E21: =C21*D21 -> 125.81874 | F21: =VLOOKUP(A21,[2]产品数据!$A:$AG,32,0) -> 40 | G21: =D21/F21 -> 0.3 | I21: =VLOOKUP(A21,[2]产品数据!$A:$R,16,0) -> 0.256 | J21: =I21*D21 -> 3.072 | K21: =VLOOKUP(A21,[2]产品数据!$A:$AE,29,0) -> 0.0168345 | L21: =K21*G21 -> 0.00505035
A22: MD2284 | B22: =VLOOKUP(A22,'[1]July 2026'!$B:$G,2,0) -> mideer Portable Gouache Paint Bucket Set | C22: 69.483 | D22: 2 | E22: =C22*D22 -> 138.966 | F22: =VLOOKUP(A22,[2]产品数据!$A:$AG,32,0) -> 10 | G22: =D22/F22 -> 0.2 | I22: =VLOOKUP(A22,[2]产品数据!$A:$R,16,0) -> 1.2 | J22: =I22*D22 -> 2.4 | K22: =VLOOKUP(A22,[2]产品数据!$A:$AE,29,0) -> 0.06860256 | L22: =K22*G22 -> 0.013720512
A23: MD2366 | B23: =VLOOKUP(A23,'[1]July 2026'!$B:$G,2,0) -> mideer Mellow Dough - Texture Play Set | C23: 41.4 | D23: 2 | E23: =C23*D23 -> 82.8 | F23: =VLOOKUP(A23,[2]产品数据!$A:$AG,32,0) -> 14 | G23: =D23/F23 -> 0.14285714 | I23: =VLOOKUP(A23,[2]产品数据!$A:$R,16,0) -> 0.87 | J23: =I23*D23 -> 1.74 | K23: =VLOOKUP(A23,[2]产品数据!$A:$AE,29,0) -> 0.059985 | L23: =K23*G23 -> 0.0085692857
A24: MD3386 | B24: =VLOOKUP(A24,'[1]July 2026'!$B:$G,2,0) -> mideer Round-Tip Stamper Washable Marker- 12 colors | C24: 24.9435 | D24: 6 | E24: =C24*D24 -> 149.661 | F24: =VLOOKUP(A24,[2]产品数据!$A:$AG,32,0) -> 24 | G24: =D24/F24 -> 0.25 | I24: =VLOOKUP(A24,[2]产品数据!$A:$R,16,0) -> 0.28 | J24: =I24*D24 -> 1.68 | K24: =VLOOKUP(A24,[2]产品数据!$A:$AE,29,0) -> 0.02167488 | L24: =K24*G24 -> 0.00541872
... A38: MD1518 | B38: =VLOOKUP(A38,'[1]July 2026'!$B:$G,2,0) -> mideer Magnetic Maze · Parking Lot | C38: 52.6815 | D38: 12 | E38: =C38*D38 -> 632.178 | F38: =VLOOKUP(A38,[2]产品数据!$A:$AG,32,0) -> 16 | G38: =D38/F38 -> 0.75 | I38: =VLOOKUP(A38,[2]产品数据!$A:$R,16,0) -> 0.75 | J38: =I38*D38 -> 9 | K38: =VLOOKUP(A38,[2]产品数据!$A:$AE,29,0) -> 0.0440592 | L38: =K38*G38 -> 0.0330444
A39: MD2261 | B39: =VLOOKUP(A39,[2]产品数据!$A:$F,4,0) -> mideer Magic Water Doodle Mat - Sports Day | C39: 54.95 | D39: 50 | E39: =C39*D39 -> 2747.5 | F39: =VLOOKUP(A39,[2]产品数据!$A:$AG,32,0) -> 15 | G39: =D39/F39 -> 3.3333333 | I39: =VLOOKUP(A39,[2]产品数据!$A:$R,16,0) -> 0.477 | J39: =I39*D39 -> 23.85 | K39: =VLOOKUP(A39,[2]产品数据!$A:$AE,29,0) -> 0.142296 | L39: =K39*G39 -> 0.47432
A40: MD2364 | B40: =VLOOKUP(A40,'[1]July 2026'!$B:$G,2,0) -> mideer Magic Dot Marker-12 | C40: 74.4855 | D40: 6 | E40: =C40*D40 -> 446.913 | F40: =VLOOKUP(A40,[2]产品数据!$A:$AG,32,0) -> 12 | G40: =D40/F40 -> 0.5 | H40: Aug.3rd in stock, send with next order | I40: =VLOOKUP(A40,[2]产品数据!$A:$R,16,0) -> 0.947 | J40: =I40*D40 -> 5.682 | K40: =VLOOKUP(A40,[2]产品数据!$A:$AE,29,0) -> 0.02897125 | L40: =K40*G40 -> 0.014485625
A41: MD2262 | B41: =VLOOKUP(A41,[2]产品数据!$A:$F,4,0) -> mideer Magic Water Doodle Mat - The Very Hungry Caterpillar | C41: 54.95 | D41: 50 | E41: =C41*D41 -> 2747.5 | F41: =VLOOKUP(A41,[2]产品数据!$A:$AG,32,0) -> 15 | G41: =D41/F41 -> 3.3333333 | H41: Aug.4th in stock， send with next order | I41: =VLOOKUP(A41,[2]产品数据!$A:$R,16,0) -> 0.4 | J41: =I41*D41 -> 20 | K41: =VLOOKUP(A41,[2]产品数据!$A:$AE,29,0) -> 0.14456475 | L41: =K41*G41 -> 0.4818825
A42: MD3428 | B42: =VLOOKUP(A42,[2]产品数据!$A:$F,4,0) -> SEE-THROUGH DRAWING PAD | C42: 46.775 | D42: 40 | E42: =C42*D42 -> 1871 | F42: =VLOOKUP(A42,[2]产品数据!$A:$AG,32,0) -> 20 | G42: =D42/F42 -> 2 | I42: =VLOOKUP(A42,[2]产品数据!$A:$R,16,0) -> 0.41 | J42: =I42*D42 -> 16.4 | K42: =VLOOKUP(A42,[2]产品数据!$A:$AE,29,0) -> 0.0240625 | L42: =K42*G42 -> 0.048125
A43: MD1745 | B43: =VLOOKUP(A43,[2]产品数据!$A:$F,4,0) -> mideer 3D Paper Craft-Forest Animals | C43: 11.95 | D43: 10 | E43: =C43*D43 -> 119.5 | F43: =VLOOKUP(A43,[2]产品数据!$A:$AG,32,0) -> 50 | G43: =D43/F43 -> 0.2 | I43: =VLOOKUP(A43,[2]产品数据!$A:$R,16,0) -> 0.13 | J43: =I43*D43 -> 1.3 | K43: =VLOOKUP(A43,[2]产品数据!$A:$AE,29,0) -> 0.0245952 | L43: =K43*G43 -> 0.00491904
A44: MD2422 | B44: =VLOOKUP(A44,[2]产品数据!$A:$F,4,0) -> mideer Scene Sticker Art | C44: 19.95 | D44: 25 | E44: =C44*D44 -> 498.75 | F44: =VLOOKUP(A44,[2]产品数据!$A:$AG,32,0) -> 48 | G44: =D44/F44 -> 0.52083333 | I44: =VLOOKUP(A44,[2]产品数据!$A:$R,16,0) -> 0.21 | J44: =I44*D44 -> 5.25 | K44: =VLOOKUP(A44,[2]产品数据!$A:$AE,29,0) -> 0.064218 | L44: =K44*G44 -> 0.033446875
A45: MD2357 | B45: =VLOOKUP(A45,[2]产品数据!$A:$F,4,0) -> mideer Twist Ruler Play Set | C45: 11.8 | D45: 30 | E45: =C45*D45 -> 354 | F45: =VLOOKUP(A45,[2]产品数据!$A:$AG,32,0) -> 60 | G45: =D45/F45 -> 0.5 | I45: =VLOOKUP(A45,[2]产品数据!$A:$R,16,0) -> 0.17 | J45: =I45*D45 -> 5.1 | K45: =VLOOKUP(A45,[2]产品数据!$A:$AE,29,0) -> 0.0330165 | L45: =K45*G45 -> 0.01650825
A46: MD1718 | B46: =VLOOKUP(A46,[2]产品数据!$A:$F,4,0) -> Mideer Projector Flashlight | C46: 24.95 | D46: 1 | E46: 0 | F46: =VLOOKUP(A46,[2]产品数据!$A:$AG,32,0) -> 60 | G46: =D46/F46 -> 0.016666667 | H46: free sample | I46: =VLOOKUP(A46,[2]产品数据!$A:$R,16,0) -> 0.19 | J46: =I46*D46 -> 0.19 | K46: =VLOOKUP(A46,[2]产品数据!$A:$AE,29,0) -> 0.06889 | L46: =K46*G46 -> 0.0011481667
A47: CT0624 | B47: =VLOOKUP(A47,[2]产品数据!$A:$F,4,0) -> mideer Colorful Magnetic Tiles - Junior Engineer Mini Tiles | C47: 54.71 | D47: 1 | E47: 0 | F47: =VLOOKUP(A47,[2]产品数据!$A:$AG,32,0) -> 24 | G47: =D47/F47 -> 0.041666667 | H47: free sample | I47: =VLOOKUP(A47,[2]产品数据!$A:$R,16,0) -> 0.46 | J47: =I47*D47 -> 0.46 | K47: =VLOOKUP(A47,[2]产品数据!$A:$AE,29,0) -> 0.0238425 | L47: =K47*G47 -> 0.0009934375
J48: =SUM(J11:J47) -> 303.264 | L48: =SUM(L11:L47) -> 1.7870747
B50: Total | D50: =SUM(D11:D47) -> 533 | E50: =SUM(E11:E47) -> 19388.984 | G50: =SUM(G11:G47) -> 25.129246 | I50: Estimated final weight | J50: =J48*1.1 -> 333.5904 | K50: Estimated final VOL | L50: =L48*1.1 -> 1.9657822
A51: REMARKS:
A52: Total amount: SAY CHINESE YUAN NINETEEN THOUSAND THREE HUNDRED AND EIGHTY-EIGHT AND NINETY-EIGHT CENTS ONLY
A53: Payment term: T/T, 100% PAYMENT before shipping
A54: 人民币招商银行收款码：支付宝Alipay
A56: The Seller | D56: The Buyer
A57: NINGBO FREE EXPLORATION TOYS MANUFACTURING CO.LTD
A58: Signed By: | D58: Signed By:

Sheet MDPLFHU00001
A1: NINGBO MIDEER E-BUSINESS CO LTD. TEL: 86-574 87253132 Email: sybil@mideertoys.com
A4: Proforma Invoice
A6: Sold To: | B6: Pangui SPA | D6: Date: | E6: 28th June,2021
A7: ADD: | B7: Suárez Mujica 411, depto 1603, Ñuñoa, Santiago, Chile claudio.morales.morgado@gmail.com
A8: CONTACT: | B8: Claudio Morales | D8: PI No.:
A9: TEL: | B9: 56989043007
A11: Item# | B11: Discription | C11: Vol | D11: weight/pcs(Kg) | E11: Unit Price(USD) | F11: pcs | G11: Amount（USD） | H11: pcs/ctn | I11: CTNS
A12: MD1103 | B12: KIDS STORYBOOK TORCH | C12: 2.72 | D12: 360 | E12: 7.01 | F12: 1000 | G12: =E12*F12 -> 7010 | H12: 20 | I12: =F12/H12 -> 50
A13: MD3083 | B13: Large animal-shaped puzzle dinosaur world | C13: 0.34 | D13: 50 | E13: 6.23 | F13: 80 | G13: =E13*F13 -> 498.4 | H13: 20 | I13: =F13/H13 -> 4
A14: MD3096 | B14: SECRECT PUZZLE-FOREST | C14: 0.24 | D14: 53.6 | E14: 4.18 | F14: 80 | G14: =E14*F14 -> 334.4 | H14: 20 | I14: =F14/H14 -> 4
A15: MD3097 | B15: SECRECT PUZZLE-OCEAN | C15: 0.3 | D15: 67 | E15: 4.18 | F15: 100 | G15: =E15*F15 -> 418 | H15: 20 | I15: =F15/H15 -> 5
A16: MD3026 | B16: Gift Box Puzzle-Dinosaur Age | C16: 0.463 | D16: 80.64 | E16: 5.38 | F16: 160 | G16: =E16*F16 -> 860.8 | H16: 8 | I16: =F16/H16 -> 20
A17: MD1035 | B17: Colorful Tangram | C17: 0.107 | D17: 33 | E17: 3.04 | F17: 160 | G17: =E17*F17 -> 486.4 | H17: 20 | I17: =F17/H17 -> 8
A18: MD4097 | B18: ORIGAMI PAPER PLANES | C18: 0.042 | D18: 19.2 | E18: 2.26 | F18: 60 | G18: =E18*F18 -> 135.6 | H18: 30 | I18: =F18/H18 -> 2
A19: MD0074 | B19: Kaleidescope-Moon | C19: 0.05 | D19: 6 | E19: 1.7 | F19: 100 | G19: =E19*F19 -> 170 | H19: 50 | I19: =F19/H19 -> 2
A20: MD0102 | B20: KALEIDOSCOPE-YOU LOOK YUMMY | C20: 0.026 | D20: 2.85 | E20: 1.7 | F20: 50 | G20: =E20*F20 -> 85 | H20: 50 | I20: =F20/H20 -> 1
A21: MD3086 | B21: 36p puzzle-YOU LOOK YUMMY | C21: 0.098 | D21: 15.12 | E21: 3.89 | F21: 36 | G21: =E21*F21 -> 140.04 | H21: 12 | I21: =F21/H21 -> 3
A22: MD2064 | B22: LETTER MAGNETS | C22: 0.056 | D22: 19.84 | E22: 2.82 | F22: 64 | G22: =E22*F22 -> 180.48 | H22: 32 | I22: =F22/H22 -> 2
A23: MD3084 | B23: Large animal-shaped puzzle elephant dream | C23: 0.17 | D23: 25 | E23: 6.23 | F23: 40 | G23: =E23*F23 -> 249.2 | H23: 20 | I23: =F23/H23 -> 2
... A27: MD3012-1 | B27: My first puzzle-Mom & Baby | C27: 0.159 | D27: 32 | E27: 3.54 | F27: 40 | G27: =E27*F27 -> 141.6 | H27: 20 | I27: =F27/H27 -> 2
A28: MD0077-1 | B28: My first puzzle-Traffic | E28: 3.54 | F28: 40 | G28: =E28*F28 -> 141.6 | I28: =F28/H28 -> #DIV/0!
A29: MD3030-1 | B29: My First Puzzle- 12345 | E29: 3.54 | F29: 20 | G29: =E29*F29 -> 70.8 | I29: =F29/H29 -> #DIV/0!
A30: MD3080 | B30: MY FIRST PUZZLE 10-IN-A-BOX | E30: 3.89 | F30: 40 | G30: =E30*F30 -> 155.6 | I30: =F30/H30 -> #DIV/0!
A31: MD3035 | B31: Round Puzzle-WHO AM I ? | E31: 3.89 | F31: 40 | G31: =E31*F31 -> 155.6 | I31: =F31/H31 -> #DIV/0!
A32: MD3075 | B32: 150P Round Puzzle -A Day in the Forest | E32: 5.59 | F32: 40 | G32: =E32*F32 -> 223.6 | I32: =F32/H32 -> #DIV/0!
A33: MD3082 | B33: 150P Round Puzzle -Wandering Through The Space | E33: 5.59 | F33: 80 | G33: =E33*F33 -> 447.2 | I33: =F33/H33 -> #DIV/0!
A34: MD4131 | B34: MARBLING PAINT KIT | E34: 5.59 | F34: 36 | G34: =E34*F34 -> 201.24 | I34: =F34/H34 -> #DIV/0!
A35: MD1120 | B35: BALANCE GAME | E35: 1.56 | F35: 128 | G35: =E35*F35 -> 199.68 | I35: =F35/H35 -> #DIV/0!
A36: MD3087 | B36: MATH&COUNT PUZZLE | E36: 2.76 | F36: 40 | G36: =E36*F36 -> 110.4 | I36: =F36/H36 -> #DIV/0!
A37: MD3110 | B37: WONDERFUL OCEAN PUZZLE | E37: 5.38 | F37: 40 | G37: =E37*F37 -> 215.2 | I37: =F37/H37 -> #DIV/0!
A38: MD4082 | B38: ORIGAMI PAPER ANIMALS | E38: 1.56 | F38: 60 | G38: =E38*F38 -> 93.6 | I38: =F38/H38 -> #DIV/0!
A39: MD6039 | B39: INSECT BOX | E39: 4.18 | F39: 36 | G39: =E39*F39 -> 150.48 | I39: =F39/H39 -> #DIV/0!
A40: MD4130 | B40: CREATIVE PAINTING | E40: 4.18 | F40: 32 | G40: =E40*F40 -> 133.76 | I40: =F40/H40 -> #DIV/0!
A41: MD2040 | B41: BLOCK GAME | C41: 0.085 | D41: 14.3 | E41: 3.96 | F41: 20 | G41: =E41*F41 -> 79.2 | H41: 20 | I41: =F41/H41 -> 1
A42: MD4133 | B42: lcd writing tablet | C42: 0.068 | D42: 12.6 | E42: 7.71 | F42: 40 | G42: =E42*F42 -> 308.4 | H42: 20 | I42: =F42/H42 -> 2
A43: MD0158 | B43: PUZZLE MAT | C43: 0.345 | D43: 32.46 | E43: 4.18 | F43: 60 | G43: =E43*F43 -> 250.8 | H43: 20 | I43: =F43/H43 -> 3
A44: MD3172 | B44: wooden peg puzzle-dinner time | C44: 0.036 | D44: 4.992 | E44: 2.76 | F44: 24 | G44: =E44*F44 -> 66.24 | H44: 24 | I44: =F44/H44 -> 1
A45: MD3173 | B45: wooden peg puzzle-bath time | C45: 0.036 | D45: 4.992 | E45: 2.76 | F45: 24 | G45: =E45*F45 -> 66.24 | H45: 24 | I45: =F45/H45 -> 1
A46: MD2088 | B46: LET'S MAKE ORIGAMI-Level 1 Beginner | C46: 0.028 | D46: 17.6 | E46: 1.98 | F46: 80 | G46: =E46*F46 -> 158.4 | H46: 40 | I46: =F46/H46 -> 2
A47: MD2090 | B47: LET'S MAKE ORIGAMI-Level 3 Advanced | C47: 0.028 | D47: 16.32 | E47: 1.98 | F47: 68 | G47: =E47*F47 -> 134.64 | H47: 34 | I47: =F47/H47 -> 2
...

Sheet MDPLFHU00001 (2)
A1: NINGBO MIDEER E-BUSINESS CO LTD. TEL: 86-574 87253132 Email: sybil@mideertoys.com
A4: Proforma Invoice
A6: Sold To: | B6: Pangui SPA | D6: Date: | E6: 28th June,2021
A7: ADD: | B7: Suárez Mujica 411, depto 1603, Ñuñoa, Santiago, Chile claudio.morales.morgado@gmail.com
A8: CONTACT: | B8: Claudio Morales | D8: PI No.:
A9: TEL: | B9: 56989043007
A11: Item# | B11: Discription | C11: Vol | D11: weight/pcs(Kg) | E11: Unit Price(USD) | F11: pcs | G11: Amount（USD） | H11: pcs/ctn | I11: CTNS
A12: MD0078-1 | B12: My first puzzle-Animal | E12: =7.69*0.46 -> 3.5374 | F12: 40 | G12: =E12*F12 -> 141.496 | H12: 20 | I12: =+F12/H12 -> 2
A13: MD3098 | B13: Gift Box Puzzle-Fairy Tale Prade | E13: =11.69*0.46 -> 5.3774 | F13: 24 | G13: =E13*F13 -> 129.0576 | H13: 8 | I13: =+F13/H13 -> 3
A14: MD2031 | B14: MIDEER BODY MAGNET | E14: =15.23*0.46 -> 7.0058 | F14: 60 | G14: =E14*F14 -> 420.348 | H14: 10 | I14: =+F14/H14 -> 6
A15: MD0107 | B15: THE PRINCESS GARDEN | E15: =3.69*0.46 -> 1.6974 | F15: 50 | G15: =E15*F15 -> 84.87 | H15: 50 | I15: =+F15/H15 -> 1
A16: MD0102 | B16: KALEIDOSCOPE-YOU LOOK YUMMY | C16: 0.026 | D16: 2.85 | E16: 1.7 | F16: 50 | G16: =E16*F16 -> 85 | H16: 50 | I16: =+F16/H16 -> 1
A17: MD0130 | B17: SOAP LAND | E17: =10.62*0.46 -> 4.8852 | F17: 24 | G17: =E17*F17 -> 117.2448 | H17: 12 | I17: =+F17/H17 -> 2
A18: MD0068 | B18: Keep It Steady | E18: =6.77*0.46 -> 3.1142 | F18: 32 | G18: =E18*F18 -> 99.6544 | H18: 32 | I18: =+F18/H18 -> 1
A19: MD1050 | B19: BALANCING GAME ELEPHANT | E19: =6.46*0.46 -> 2.9716 | F19: 48 | G19: =E19*F19 -> 142.6368 | H19: 48 | I19: =+F19/H19 -> 1
A20: MD1120 | B20: BALANCE GAME | E20: =3.38*0.46 -> 1.5548 | F20: 64 | G20: =E20*F20 -> 99.5072 | H20: 64 | I20: =+F20/H20 -> 1
A21: MD3099 | B21: 150P Round Puzzle -ANIMALS AROUND THE WORLD | E21: =12.15*0.46 -> 5.589 | F21: 32 | G21: =E21*F21 -> 178.848 | H21: 8 | I21: =+F21/H21 -> 4
A22: MD3027 | B22: Gift Box Puzzle- Our World | E22: =11.69*0.46 -> 5.3774 | F22: 24 | G22: =E22*F22 -> 129.0576 | H22: 8 | I22: =+F22/H22 -> 3
A92: Total | C92: =SUM(C12:C71) -> 0.026 | D92: =SUM(D12:D71) -> 2.85 | F92: =SUM(F12:F87) -> 448 | G92: =SUM(G12:G89) -> 1627.7204 | I92: =SUM(I12:I87) -> 25
A93: REMARKS: | C93: =C92*1.1 -> 0.0286 | D93: =D92*1.1 -> 3.135
A94: Total amount: SAY TOTAL SIXTEEN THOUSAN THREE POINT TWENTY USD ONLY
A95: Payment term: T/T, 100% PAYMENT against e-mail or faxed documents
A97: Bank Information of MiDeer toys:
A98: BENEFICIARY: BENEFICIARY: NINGBO MIDEER E-BUSINESS CO LTD.
A99: BEN'S ADD.: ROOM 339, BUILDING 6, NO.1000 JICHANG ROAD, HAISHU DISTRICT, NINGBO CITY, ZHEJIANG, CHINA
A100: BEN'S BANK: BANK OF NINGBO
A101: BEN'S BANK'S ADD.: NO. 345 NINGDONG ROAD, YINZHOU DISTRICT, NINGBO, P.R.CHINA, 315042
A102: BEN'S ACCOUNT：30012025000087570
A103: SWIFT CODE: BKNBCN2N
A105: The Seller | D105: The Buyer
A106: NINGBO MIDEER E-BUSINESS CO LTD.
A107: Signed By: | D107: Signed By:
